Workbook

Sheet README
A1: Paper Extraction Sheet — IT22638168 (Document 2)
A3: Working companion to the Literature Review Master Plan. This is Document 2 of that plan: one row per paper, screened and extracted as the literature search proceeds.
A5: Sheets in this workbook
A6: Master Extraction Sheet — the main tracker. One row per paper. Log every candidate here, including ones you reject — a fast 'Screened Out' entry is cheaper than re-finding a paper later.
A7: Progress Tracker — a live dashboard (formula-driven) showing how many papers you've extracted per topic against the targets from the Master Plan's Section C. Updates automatically as you fill in the Master sheet.
A8: Behavioural Signal Track — the dedicated Section G tracker. Resolve this one first: the fusion methodology (§3.2.6) depends on its outcome.
A10: How to use the Master Extraction Sheet
A11: 1. Every candidate paper gets a row, the moment you find it — set Status to 'Candidate' immediately, even before reading it properly.
A12: 2. After screening (checking it's a real, relevant, sufficiently high-quality source), update Status to 'Screened Out' (with a one-line reason in Notes) or move on to full extraction.
A13: 3. Fill in every column you can once you've read the paper properly, and set Status to 'Extracted'.
A14: 4. Set 'Verified Real?' to Yes only once you have personally opened the DOI/link and confirmed the paper exists and says what you're citing it for. Given this project's earlier history with fabricated references, no paper moves to 'Cited in Final' with this column still on 'Pending'.
A15: 5. Set Status to 'Cited in Final' only once it's actually used in the written literature review chapter.
... A23: Never mark a paper 'Verified Real? = Yes' from a search-result snippet alone. Open the actual DOI or publisher link yourself. This exact project had ten fabricated references make it into an earlier proposal draft before being caught — this sheet exists partly to make that structurally harder to repeat.

Sheet Master Extraction Sheet
A1: ID | B1: Topic | C1: Sub-topic (Behavioural only) | D1: Status | E1: Tier | F1: Verified Real? | G1: Authors | H1: Year | I1: Title | J1: Venue | K1: DOI / Stable Link | L1: Research Problem | M1: Dataset | N1: Population / Context | O1: Method | P1: Model / Algorithm | Q1: Input Modality | R1: Output | S1: Evaluation Metrics | T1: Results | U1: Limitations (stated by authors) | V1: Relevance to IT22638168 | W1: Gap Identified | X1: Technology/Technique to Reuse | Y1: Notes
A2: M1 | B2: Maternal Mental Health / Sri Lanka Context | C2: (N/A — not Behavioural Track) | D2: Extracted | E2: Tier 1 | F2: Yes | G2: Agampodi, S.B.; Agampodi, T.C. | H2: 2013 | I2: Antenatal Depression in Anuradhapura, Sri Lanka and the Factor Structure of the Sinhalese Version of Edinburgh Post Partum Depression Scale among Pregnant Women | J2: PLOS ONE | K2: https://doi.org/10.1371/journal.pone.0069708 | L2: Prevalence/correlates of antenatal depression and Sinhala EPDS structure | M2: 376 pregnant women | N2: 24–36 weeks, Anuradhapura Sri Lanka | O2: Cross-sectional cluster sample; Sinhala EPDS | P2: EPDS/factor analysis | Q2: Questionnaire | R2: Antenatal depression | S2: EPDS prevalence; factor analysis | T2: 16.2% prevalence; Sinhala EPDS two-factor solution | U2: Single district; screening not clinical diagnosis | V2: Direct Sri Lankan evidence and Sinhala screening reference | W2: Need digital, conversational, continuous support rather than periodic screening | X2: Sinhala emotional categories and self-report validation | Y2: Strong contextual foundation
A3: M2 | B3: Maternal Mental Health / Sri Lanka Context | C3: (N/A — not Behavioural Track) | D3: Extracted | E3: Tier 1 | F3: Yes | G3: Suraweera, C.; Perera, I.; Isuru, L.L.A.; Galhenage, J. | H3: 2021 | I3: Prevalence and associated factors of antenatal depression of women attending antenatal clinics in two tertiary care maternity hospitals in Sri Lanka | J3: BJPsych Open | K3: https://doi.org/10.1192/bjo.2021.776 | L3: Measure antenatal depression in Colombo tertiary hospitals | M3: 536 pregnant women | N3: Colombo, Sri Lanka | O3: Cross-sectional; EPDS | P3: EPDS | Q3: Questionnaire | R3: Depression prevalence | S3: EPDS | T3: 33.6% screened positive | U3: Hospital-based cross-sectional study | V3: Demonstrates substantial antenatal emotional-health need | W3: Need scalable support between clinical contacts | X3: Problem justification
A4: M3 | B4: Maternal Mental Health / Sri Lanka Context | C4: (N/A — not Behavioural Track) | D4: Extracted | E4: Tier 1 | F4: Yes | G4: Authors as listed in BMC source | H4: 2021 | I4: Predictors and occurrence of antenatal depressive symptoms in Galle, Sri Lanka: a mixed-methods cross-sectional study | J4: BMC Pregnancy and Childbirth | K4: https://doi.org/10.1186/s12884-021-04239-w | L4: Prevalence/risk factors and provider perspectives | M4: 505 pregnant women + midwife interviews | N4: Galle, Sri Lanka | O4: Mixed methods; EPDS, MSPSS, PRAQ-R2, interviews | P4: Regression + thematic analysis | Q4: Questionnaire/interview | R4: Depressive symptoms/risk factors | S4: Prevalence, ORs | T4: 7.5%; social support and health factors associated | U4: Single region | V4: Shows psychosocial/social-support context | W4: Need culturally/contextually appropriate support | X4: Supportive response context
A5: M4 | B5: Maternal Mental Health / Sri Lanka Context | C5: (N/A — not Behavioural Track) | D5: Extracted | E5: Tier 1 | F5: Yes | G5: Palfreyman et al. | H5: 2021 | I5: Addressing Psychosocial Vulnerabilities Through Antenatal Care—Depression, Suicidal Ideation, and Behavior: A Study Among Urban Sri Lankan Women | J5: Frontiers in Psychiatry | K5: https://doi.org/10.3389/fpsyt.2021.554808 | L5: Characterize depressive symptoms and psychosocial vulnerabilities | M5: 1000 antenatal women | N5: Gampaha District, Sri Lanka | O5: Cross-sectional screening | P5: EPDS + modified C-SSRS | Q5: Questionnaire | R5: Depression/SIB risk | S5: Prevalence and regression | T5: Identified depressive symptoms and self-harm-related vulnerabilities | U5: Screening design | V5: Important safety context for an emotional-support system | W5: Digital support needs explicit escalation/safety boundaries | X5: Safety design
A6: M5 | B6: Maternal Mental Health / Sri Lanka Context | C6: (N/A — not Behavioural Track) | D6: Extracted | E6: Tier 1 | F6: Yes | G6: Priyadarshanie et al. | H6: 2024 | I6: Risk factors for antenatal anxiety: a cross-sectional study in field antenatal clinics in Sri Lanka | J6: BMJ Open | K6: https://doi.org/10.1136/bmjopen-2024-083991 | L6: Prevalence/factors affecting antenatal anxiety | M6: 535 first-trimester women | N6: Colombo District field antenatal clinics | O6: Cross-sectional cohort analysis | P6: PASS-S + regression | Q6: Questionnaire/records | R6: Antenatal anxiety | S6: PASS threshold and adjusted ORs | T6: 34.4% prevalence; multiple psychosocial/financial/family risks | U6: Observational/first-trimester sample | V6: Recent Sri Lankan anxiety evidence | W6: Need context-aware support beyond screening | X6: Use PASS-S/self-report concepts in evaluation
A7: M6 | B7: Maternal Mental Health / Sri Lanka Context | C7: (N/A — not Behavioural Track) | D7: Extracted | E7: Tier 1 | F7: Yes | G7: Agampodi et al. | H7: 2023 | I7: Incorporating early pregnancy mental health screening and management into routine maternal care: experience from the Rajarata Pregnancy Cohort (RaPCo), Sri Lanka | J7: BMC | K7: https://pmc.ncbi.nlm.nih.gov/articles/PMC10533714/ | L7: Integrate screening/management into routine maternal care | M7: 3074 pregnant women | N7: Rajarata Pregnancy Cohort, Sri Lanka | O7: Two-stage screening + targeted interventions | P7: EPDS + clinical interview/MH GAP | Q7: Screening/interview | R7: Mental-health risk and intervention pathway | S7: Screening positivity and follow-up | T7: EPDS positive 23% first trimester, 14% second | U7: Program-specific context | V7: Shows integration with antenatal care is feasible | W7: Digital conversational support can complement screening | X7: Doctor escalation/integration model
A8: A1 | B8: Existing Pregnancy-Support & Mental-Health Apps | C8: (N/A — not Behavioural Track) | D8: Extracted | E8: Tier 1 | F8: Yes | G8: Tsai et al. | H8: 2022 | I8: Evaluating the effectiveness and quality of mobile applications for perinatal depression and anxiety: a systematic review and meta-analysis | J8: Journal of Affective Disorders | K8: https://doi.org/10.1016/j.jad.2021.09.106 | L8: Effectiveness and quality of perinatal apps | M8: 7 studies meta-analyzed; 74 app-store apps | N8: Perinatal women/apps | O8: Systematic review/meta-analysis + MARS | P8: MARS | Q8: Mobile apps | R8: Depression/anxiety outcomes | S8: SMD; MARS | T8: No significant short-term depression/anxiety improvement; mean MARS 3.6/5 | U8: Few clinically tested apps | V8: Shows quality/evidence gap in existing apps | W8: Need stronger evidence and adaptive support | X8: MARS-style quality evaluation
A9: A2 | B9: Existing Pregnancy-Support & Mental-Health Apps | C9: (N/A — not Behavioural Track) | D9: Extracted | E9: Tier 1 | F9: Yes | G9: Hussain-Shamsy et al. | H9: 2020 | I9: Mobile Health for Perinatal Depression and Anxiety: Scoping Review | J9: JMIR | K9: https://pubmed.ncbi.nlm.nih.gov/32281939/ | L9: Map mobile tools for perinatal depression/anxiety | M9: 22 unique studies | N9: Pregnant/postpartum women | O9: Scoping review | P9: Review synthesis | Q9: Apps/SMS | R9: Prevention/screening/treatment | S9: Descriptive synthesis | T9: Apps 54%; SMS 45%; psychoeducation common | U9: Limited continuity/sustainability evidence | V9: Positions current mHealth landscape | W9: Few tools combine conversational support with passive mood inference | X9: Existing-system taxonomy
A10: A3 | B10: Existing Pregnancy-Support & Mental-Health Apps | C10: (N/A — not Behavioural Track) | D10: Extracted | E10: Tier 1 | F10: Yes | G10: Arifin et al. | H10: 2024 | I10: An evaluation of digital intervention for perinatal depression and anxiety: A systematic review | J10: AIMS Public Health | K10: https://doi.org/10.3934/publichealth.2024025 | L10: Review design characteristics of digital perinatal interventions | M10: 12 intervention studies | N10: Perinatal women | O10: PRISMA systematic review | P10: Narrative synthesis | Q10: Digital CBT/mindfulness | R10: Depression/anxiety | S10: Study outcomes | T10: CBT and mindfulness dominated; reduced depressive symptoms reported | U10: Only one study included partner support; heterogeneous designs | V10: Supports intervention-design considerations | W10: Need personalized and culturally localized approaches | X10: Content strategy
A11: A4 | B11: Existing Pregnancy-Support & Mental-Health Apps | C11: (N/A — not Behavioural Track) | D11: Extracted | E11: Tier 1 | F11: Yes | G11: Hussain et al. | H11: 2018 | I11: User assessments and the use of information from MomConnect, a mobile phone text-based information service, by pregnant women and new mothers in South Africa | J11: BMJ Global Health | K11: https://doi.org/10.1136/bmjgh-2017-000561 | L11: Understand acceptability/use of maternal mobile messaging | M11: 32 interviews + 7 focus groups | N11: Pregnant/new mothers, South Africa | O11: Qualitative evaluation | P11: Thematic analysis | Q11: SMS/mobile helpdesk | R11: User acceptability | S11: Qualitative themes | T11: Women valued content and delivery medium | U11: South Africa-specific | V11: Evidence that maternal mobile support can be accepted | W11: Need emotional/adaptive functionality | X11: Accessibility/usability principles
A12: C1 | B12: Conversational Agents for Mental Health | C12: (N/A — not Behavioural Track) | D12: Extracted | E12: Tier 1 | F12: Yes | G12: Li et al. | H12: 2023 | I12: Systematic review and meta-analysis of AI-based conversational agents for promoting mental health and well-being | J12: npj Digital Medicine | K12: https://doi.org/10.1038/s41746-023-00979-5 | L12: Effectiveness of AI conversational agents | M12: 35 studies; 15 RCTs | N12: Mental-health populations | O12: Systematic review/meta-analysis | P12: AI CAs | Q12: Text/multimodal | R12: Depression/distress/wellbeing | S12: Hedges g | T12: Depression g=0.64; distress g=0.70; wellbeing nonsignificant | U12: Heterogeneity | V12: Supports CA potential but cautions against overclaiming wellbeing | W12: Need context-specific, adaptive systems | X12: Evaluation/moderators
A13: C2 | B13: Conversational Agents for Mental Health | C13: (N/A — not Behavioural Track) | D13: Extracted | E13: Tier 1 | F13: Yes | G13: He et al. | H13: 2023 | I13: Conversational Agent Interventions for Mental Health Problems: Systematic Review and Meta-analysis of Randomized Controlled Trials | J13: JMIR Mental Health | K13: https://doi.org/10.2196/43862 | L13: Effectiveness and moderators of CA interventions | M13: RCTs in systematic review | N13: Mental health populations | O13: Systematic review/meta-analysis | P13: Conversational agents | Q13: Conversational | R13: Mental health outcomes | S13: Effect sizes/moderators | T13: Personalization and empathic response associated with larger effects | U13: Long-term effects less consistent | V13: Strong justification for adaptive/empathic responses | W13: Need objective mood-adaptation mechanisms | X13: Personalization/empathy
A14: C3 | B14: Conversational Agents for Mental Health | C14: (N/A — not Behavioural Track) | D14: Extracted | E14: Tier 1 | F14: Yes | G14: Sanjeewa et al. | H14: 2024 | I14: Empathic Conversational Agent Platform Designs and Their Evaluation in the Context of Mental Health: Systematic Review | J14: JMIR Mental Health | K14: https://doi.org/10.2196/50701 | L14: Architectures/evaluation of empathic CAs | M14: 19 articles | N14: Mental health CAs | O14: Systematic review | P14: ML/hybrid/rule CAs | Q14: Text/voice | R14: Emotion/empathy | S14: Technical + human evaluation | T14: 63% ML; hybrid often more nuanced; 84% human evaluation | U14: Only 26% directly evaluated empathy; metrics vary | V14: Directly informs architecture/evaluation | W14: Need standardized empathy and emotion evaluation | X14: Human evaluation
... A16: C5 | B16: Conversational Agents for Mental Health | C16: (N/A — not Behavioural Track) | D16: Extracted | E16: Tier 1 | F16: Yes | G16: Fitzpatrick et al. | H16: 2017 | I16: Delivering Cognitive Behavior Therapy to Young Adults With Symptoms of Depression and Anxiety Using a Fully Automated Conversational Agent (Woebot): A Randomized Controlled Trial | J16: JMIR Mental Health | K16: https://doi.org/10.2196/mental.7785 | L16: Feasibility/efficacy of automated CBT chatbot | M16: 70 young adults | N16: College students | O16: Unblinded RCT | P16: Woebot CBT agent | Q16: Text chatbot | R16: Depression/anxiety | S16: PHQ-9/GAD-7 | T16: Significant depression reduction vs information control | U16: Small, short study | V16: Existing benchmark for mental-health chatbot | W16: Not pregnancy-specific or multimodal | X16: Evaluation design
A17: C6 | B17: Conversational Agents for Mental Health | C17: (N/A — not Behavioural Track) | D17: Extracted | E17: Tier 1 | F17: Yes | G17: McAlister et al. | H17: 2025 | I17: Chatbot to Support the Mental Health Needs of Pregnant and Postpartum Women (Moment for Parents): Design and Pilot Study | J17: JMIR Formative Research | K17: https://pubmed.ncbi.nlm.nih.gov/40202166/ | L17: Tailored perinatal mental-health chatbot | M17: 43 interviews; 108 pilot users | N17: Pregnant/postpartum women | O17: Human-centered design + pilot | P17: Rules-based chatbot | Q17: Text | R17: Perinatal support | S17: Re-engagement/usability/satisfaction | T17: 63.9% re-engaged; 93.3% found relevant | U17: Repetitive content; limited response options | V17: Closest direct comparator | W17: No multimodal mood inference; not Sinhala/Sri Lanka | X17: User-centered content design | Y17: Key existing system
A18: F1 | B18: Facial Emotion Recognition (incl. Head-Pose) | C18: (N/A — not Behavioural Track) | D18: Extracted | E18: Tier 1 | F18: Yes | G18: Survey authors (see source) | H18: 2019 | I18: Facial Expression Recognition: A Survey | J18: Symmetry | K18: https://doi.org/10.3390/sym11101189 | L18: Survey FER methods, datasets, evaluation | M18: 17 datasets reviewed | N18: FER research | O18: Survey | P18: CNN/deep learning taxonomy | Q18: Face | R18: Emotion classes | S18: Surveyed metrics | T18: Summarizes methods/datasets/challenges | U18: Older survey | V18: FER foundations | W18: Real-world robustness remains | X18: Dataset/metric selection
A19: F2 | B19: Facial Emotion Recognition (incl. Head-Pose) | C19: (N/A — not Behavioural Track) | D19: Extracted | E19: Tier 1 | F19: Yes | G19: Mollahosseini, A.; Hasani, B.; Mahoor, M.H. | H19: 2019 | I19: AffectNet: A Database for Facial Expression, Valence, and Arousal Computing in the Wild | J19: IEEE Transactions on Affective Computing | K19: https://doi.org/10.1109/TAFFC.2017.2740923 | L19: Large in-the-wild affect dataset | M19: >1M images; about half manually annotated | N19: Web-scraped diverse faces | O19: Dataset + CNN baselines | P19: CNN | Q19: Face | R19: 7 expressions + valence/arousal | S19: Accuracy/RMSE | T19: Large real-world dataset with baseline deep models | U19: In-the-wild variability and demographic issues | V19: Supports AffectNet use | W19: Need local/device-specific evaluation | X19: AffectNet
A20: F3 | B20: Facial Emotion Recognition (incl. Head-Pose) | C20: (N/A — not Behavioural Track) | D20: Extracted | E20: Tier 1 | F20: Yes | G20: Sandler et al. | H20: 2018 | I20: MobileNetV2: Inverted Residuals and Linear Bottlenecks | J20: CVPR | K20: https://doi.org/10.1109/CVPR.2018.00474 | L20: Efficient mobile vision architecture | M20: ImageNet/COCO/VOC | N20: Mobile/resource-constrained devices | O20: Architecture study | P20: MobileNetV2 | Q20: Image | R20: Vision tasks | S20: Accuracy/MAdds/latency/params | T20: Strong accuracy-efficiency trade-off | U20: Not FER-specific | V20: Basis for on-device FER model | W20: FER-specific mobile validation needed | X20: MobileNetV2 transfer learning
A21: F4 | B21: Facial Emotion Recognition (incl. Head-Pose) | C21: (N/A — not Behavioural Track) | D21: Extracted | E21: Tier 1 | F21: Yes | G21: Zhu et al. | H21: 2024 | I21: A study on expression recognition based on improved MobileNetV2 network | J21: Scientific Reports | K21: https://doi.org/10.1038/s41598-024-58736-x | L21: Improve lightweight MobileNetV2 FER performance | M21: Facial expression dataset | N21: Expression recognition | O21: Improved MobileNetV2 | P21: I-MobileNetV2 | Q21: Face | R21: Emotion | S21: Accuracy/efficiency | T21: Targets better accuracy and real-time performance | U21: Improved architecture increases complexity | V21: Current evidence for MobileNetV2 family | W21: Need mid-range Android validation | X21: MobileNetV2
A22: F5 | B22: Facial Emotion Recognition (incl. Head-Pose) | C22: (N/A — not Behavioural Track) | D22: Extracted | E22: Tier 1 | F22: Yes | G22: Yang, F.; Zhang, Q.; Zheng, C.; Qiu, G. | H22: 2018 | I22: In-the-wild Facial Expression Recognition in Extreme Poses | J22: arXiv | K22: https://arxiv.org/abs/1811.02194 | L22: FER under extreme head poses | M22: Labeled multi-pose face data | N22: In-the-wild extreme poses | O22: Pose grouping + feature fusion | P22: SIFT/LBP + deep features | Q22: Face | R22: 6 basic expressions | S22: Recognition accuracy | T22: Pose-aware grouping improved recognition | U22: Adds pose-specific complexity | V22: Direct deployment risk for phone camera | W22: Need head-pose test protocol | X22: Pose-aware evaluation
A23: F6 | B23: Facial Emotion Recognition (incl. Head-Pose) | C23: (N/A — not Behavioural Track) | D23: Extracted | E23: Tier 1 | F23: Yes | G23: Dominguez-Catena, I.; Paternain, D.; Galar, M. | H23: 2024 | I23: Metrics for Dataset Demographic Bias: A Case Study on Facial Expression Recognition | J23: IEEE TPAMI | K23: https://doi.org/10.1109/TPAMI.2024.3361979 | L23: Measure demographic bias in FER datasets | M23: 20 FER datasets | N23: Multiple demographic groups | O23: Bias metric taxonomy + case study | P23: FER datasets/models | Q23: Face | R23: Bias/fairness | S23: Demographic bias metrics | T23: Dataset imbalance can drive unfairness; reduced metric subset proposed | U23: Dataset-level focus | V23: Important fairness consideration | W23: Need Sri Lankan/local demographic evaluation | X23: Bias metrics
A24: E1 | B24: English Sentiment / Transformers | C24: (N/A — not Behavioural Track) | D24: Extracted | E24: Tier 1 | F24: Yes | G24: Sanh et al. | H24: 2019 | I24: DistilBERT, a distilled version of BERT: smaller, faster, cheaper and lighter | J24: arXiv | K24: https://arxiv.org/abs/1910.01108 | L24: Compress BERT for efficient NLP | M24: Pretraining + NLP benchmarks | N24: General NLP | O24: Knowledge distillation | P24: DistilBERT | Q24: Text | R24: NLP task predictions | S24: Model size/speed/task performance | T24: 40% smaller, 60% faster; ~97% language understanding retained | U24: Not pregnancy-specific | V24: Justifies efficient transformer | W24: Domain shift to pregnancy chat | X24: DistilBERT
A25: E2 | B25: English Sentiment / Transformers | C25: (N/A — not Behavioural Track) | D25: Extracted | E25: Tier 1 | F25: Yes | G25: Devlin et al. | H25: 2019 | I25: BERT: Pre-training of Deep Bidirectional Transformers for Language Understanding | J25: NAACL | K25: https://doi.org/10.18653/v1/N19-1423 | L25: Contextual language representation | M25: Large unlabeled corpora + GLUE | N25: General NLP | O25: Pretraining + fine-tuning | P25: BERT | Q25: Text | R25: NLP tasks | S25: GLUE/MultiNLI/SQuAD | T25: State-of-the-art on 11 tasks at publication | U25: Resource-heavy | V25: Foundational transformer rationale | W25: Need lightweight/domain-appropriate model | X25: Transformer fine-tuning concept
A26: E3 | B26: English Sentiment / Transformers | C26: (N/A — not Behavioural Track) | D26: Extracted | E26: Tier 1 | F26: Yes | G26: Acheampong, F.A.; Wenyu, C.; Nunoo-Mensah, H. | H26: 2020 | I26: Text-based emotion detection: Advances, challenges, and opportunities | J26: Engineering Reports | K26: https://doi.org/10.1002/eng2.12189 | L26: Review text emotion detection | M26: Literature review | N26: Text emotion | O26: Review | P26: ML/deep learning | Q26: Text | R26: Emotion | S26: Survey | T26: Reviews classical/deep approaches and challenges | U26: Review-level evidence | V26: Supports text signal limitations | W26: Text alone can be ambiguous | X26: Use multimodality to complement text
A27: S1 | B27: Sinhala / Low-Resource NLP | C27: (N/A — not Behavioural Track) | D27: Extracted | E27: Tier 1 | F27: Yes | G27: Peiris, Y.N.S. | H27: 2021 | I27: Sentiment Analysis for the Sinhala Language with BERT Based Language Model | J27: IIT Sri Lanka repository | K27: http://dlib.iit.ac.lk/xmlui/handle/123456789/849 | L27: Sinhala sentiment using transformer | M27: Sinhala news comments; binary/multiclass | N27: Sinhala | O27: LaBSE + classifier | P27: LaBSE | Q27: Text | R27: Sentiment | S27: F1 | T27: 89.82% binary; 64.72% multiclass | U27: News comments; not pregnancy context | V27: Benchmark for Sinhala sentiment | W27: Pregnancy-domain Sinhala data absent | X27: Benchmark against lexicon
A28: S2 | B28: Sinhala / Low-Resource NLP | C28: (N/A — not Behavioural Track) | D28: Extracted | E28: Tier 1 | F28: Yes | G28: Ranasinghe et al. | H28: 2025 | I28: Sinhala Encoder-only Language Models and Evaluation | J28: ACL 2025 | K28: https://doi.org/10.18653/v1/2025.acl-long.422 | L28: Sinhala LM resource and benchmark scarcity | M28: Large Sinhala corpus + Sinhala-GLUE | N28: Sinhala | O28: Train LMs + benchmark | P28: Sinhala encoder LMs | Q28: Text | R28: Multiple NLP tasks | S28: Sinhala-GLUE | T28: Sinhala-specific LMs outperform popular multilingual LMs | U28: Resource scarcity remains | V28: Current Sinhala NLP landscape | W28: Pregnancy-specific sentiment still underexplored | X28: Consider Sinhala-specific model as future alternative
A29: S3 | B29: Sinhala / Low-Resource NLP | C29: (N/A — not Behavioural Track) | D29: Extracted | E29: Tier 1 | F29: Yes | G29: Weeraprameshwara et al. | H29: 2022 | I29: Sinhala Sentence Embedding: A Two-Tiered Structure for Low-Resource Languages | J29: PACLIC | K29: https://aclanthology.org/2022.paclic-1.36/ | L29: Sinhala sentence representation in low-resource setting | M29: Sinhala text | N29: Sinhala | O29: Two-tier sentence embedding | P29: Sentence embedding architecture | Q29: Text | R29: Sentence representations | S29: Embedding evaluation | T29: Proposes Sinhala embedding approach | U29: Low-resource setting | V29: Supports Sinhala semantic processing | W29: Emotion-specific pregnancy data | X29: Future embedding baseline
A30: S4 | B30: Sinhala / Low-Resource NLP | C30: (N/A — not Behavioural Track) | D30: Extracted | E30: Tier 1 | F30: Yes | G30: De Mel et al. | H30: 2025 | I30: Sinhala Transliteration: A Comparative Analysis Between Rule-based and Seq2Seq Approaches | J30: IndoNLP 2025 | K30: https://aclanthology.org/2025.indonlp-1.19/ | L30: Handle Romanized Sinhala | M30: Romanized Sinhala | N30: Sinhala/English mixed typing | O30: Rule-based vs Transformer | P30: Seq2Seq Transformer | Q30: Text | R30: Transliteration | S30: Transliteration quality | T30: Transformer captured ad-hoc patterns better | U30: Not sentiment-specific | V30: Important for real user input | W30: Romanized Sinhala handling not in core proposal | X30: Future input normalization | Y30: Scope consideration
A31: S5 | B31: Sinhala / Low-Resource NLP | C31: (N/A — not Behavioural Track) | D31: Extracted | E31: Tier 1 | F31: Yes | G31: Perera, P.S.; Sumanathilaka, D.K. | H31: 2025 | I31: A Low-Resource Speech-Driven NLP Pipeline for Sinhala Dyslexia Assistance | J31: RANLP 2025 | K31: https://aclanthology.org/2025.ranlp-1.106/ | L31: Build Sinhala assistive NLP under low-resource constraints | M31: Sinhala speech/text | N31: Sinhala | O31: Whisper + SinBERT + mT5/Mistral | P31: SinBERT etc. | Q31: Speech/text | R31: Correction | S31: Accuracy | T31: 66% transcription; 70% correction; 65% overall | U31: Limited datasets | V31: Shows current Sinhala NLP feasibility and data limits | W31: Pregnancy sentiment data still missing | X31: Data/evaluation discipline
A32: MF1 | B32: Multimodal Fusion | C32: (N/A — not Behavioural Track) | D32: Extracted | E32: Tier 1 | F32: Yes | G32: Lian, H.; Lu, C.; Li, S.; Zhao, Y.; Tang, C.; Zong, Y. | H32: 2023 | I32: A Survey of Deep Learning-Based Multimodal Emotion Recognition: Speech, Text, and Face | J32: Entropy | K32: https://doi.org/10.3390/e25101440 | L32: Survey multimodal emotion recognition | M32: Multiple MER datasets | N32: Affective computing | O32: Survey | P32: Deep multimodal methods | Q32: Face/text/speech | R32: Emotion | S32: Survey | T32: Categorizes multimodal methods and datasets | U32: Modality/data alignment challenges | V32: Supports multimodal framing | W32: Face+text in pregnancy-specific setting | X32: Fusion taxonomy
A33: MF2 | B33: Multimodal Fusion | C33: (N/A — not Behavioural Track) | D33: Extracted | E33: Tier 1 | F33: Yes | G33: Ezzameli, K.; Mahersia, H. | H33: 2023 | I33: Emotion recognition from unimodal to multimodal analysis: A review | J33: Information Fusion | K33: https://doi.org/10.1016/j.inffus.2023.101847 | L33: Review unimodal/multimodal evolution | M33: Literature review | N33: Emotion recognition | O33: Review | P33: CNN/LSTM/Transformer/fusion | Q33: Multiple | R33: Emotion | S33: Review | T33: Multimodal combinations often improve recognition; transformers strong for text | U33: Generalization/fusion complexity | V33: Supports two-modality fusion | W33: Need principled weighting/evaluation | X33: Compare early/late fusion
A34: MF3 | B34: Multimodal Fusion | C34: (N/A — not Behavioural Track) | D34: Extracted | E34: Tier 1 | F34: Yes | G34: Survey authors | H34: 2023 | I34: A review of multimodal emotion recognition from datasets, preprocessing, features, and fusion methods | J34: Neurocomputing | K34: https://doi.org/10.1016/j.neucom.2023.126866 | L34: Review datasets, preprocessing and fusion | M34: Multiple MER datasets | N34: Multimodal emotion research | O34: Survey | P34: Fusion taxonomy | Q34: Face/text/voice/behavior | R34: Emotion | S34: Review | T34: Highlights preprocessing, features and fusion strategies | U34: Alignment/missing modality challenges | V34: Supports confidence-aware fusion | W34: Need simple robust fusion for undergraduate deployment | X34: Late/decision fusion
A35: MF4 | B35: Multimodal Fusion | C35: (N/A — not Behavioural Track) | D35: Extracted | E35: Tier 1 | F35: Yes | G35: Survey authors | H35: 2023 | I35: Survey on multimodal approaches to emotion recognition | J35: Neurocomputing | K35: https://doi.org/10.1016/j.neucom.2023.126693 | L35: Survey multimodal emotion recognition | M35: Literature review | N35: Multimodal affective computing | O35: Survey | P35: Multimodal approaches | Q35: Multiple | R35: Emotion | S35: Review | T35: Summarizes multimodal emotion approaches | U35: Heterogeneous modalities | V35: Positions project in MER field | W35: Pregnancy/Sinhala-specific fusion | X35: Architecture comparison
A36: AD1 | B36: Adaptive / Affect-Conditioned Response | C36: (N/A — not Behavioural Track) | D36: Extracted | E36: Tier 1 | F36: Yes | G36: Sanjeewa et al. | H36: 2024 | I36: Empathic Conversational Agent Platform Designs and Their Evaluation in the Context of Mental Health: Systematic Review | J36: JMIR Mental Health | K36: https://doi.org/10.2196/50701 | L36: Empathic CA architectures/evaluation | M36: 19 articles | N36: Mental health CAs | O36: Systematic review | P36: ML/hybrid/rule | Q36: Text/voice | R36: Emotion/empathy | S36: Technical + human evaluation | T36: Hybrid engines often more nuanced; human evaluation common | U36: Inconsistent empathy measures | V36: Direct architecture/evaluation guidance | W36: Need mood-conditioned pregnancy CA | X36: Human tone evaluation
A37: AD2 | B37: Adaptive / Affect-Conditioned Response | C37: (N/A — not Behavioural Track) | D37: Extracted | E37: Tier 1 | F37: Yes | G37: Morris et al. | H37: 2018 | I37: Towards an Artificially Empathic Conversational Agent for Mental Health Applications: System Design and User Perceptions | J37: JMIR | K37: https://doi.org/10.2196/e10148 | L37: Personalized empathic response | M37: 37,169 ratings; N=1284 experiment | N37: Mental health support | O37: Retrieval + embeddings | P37: Information retrieval | Q37: Text | R37: Empathy | S37: User ratings | T37: 79.2% acceptable; human responses preferred | U37: Nonhuman empathy limitations | V37: Supports cautious adaptive tone | W37: Need objective mood detection linked to response | X37: User perception evaluation
A38: AD3 | B38: Adaptive / Affect-Conditioned Response | C38: (N/A — not Behavioural Track) | D38: Extracted | E38: Tier 1 | F38: Yes | G38: Kim, K. et al. | H38: 2025 | I38: From Seconds to Sentiments: Differential Effects of Chatbot Response Latency on Customer Evaluations | J38: International Journal of Human–Computer Interaction | K38: https://doi.org/10.1080/10447318.2025.2508915 | L38: Effect of chatbot response latency | M38: Two scenario experiments | N38: Chatbot users | O38: Controlled experiments | P38: Statistical analysis | Q38: Chat | R38: Satisfaction/perception | S38: User evaluation | T38: Longer latency reduced satisfaction; emotional support moderated effects | U38: Scenario-based | V38: Supports latency testing | W38: Need maternal/emotional support context | X38: Latency benchmark
A39: AD4 | B39: Adaptive / Affect-Conditioned Response | C39: (N/A — not Behavioural Track) | D39: Extracted | E39: Tier 1 | F39: Yes | G39: Fido trial authors | H39: 2024 | I39: Effectiveness of a Web-based and Mobile Therapy Chatbot on Anxiety and Depressive Symptoms in Subclinical Young Adults: Randomized Controlled Trial | J39: JMIR | K39: https://pubmed.ncbi.nlm.nih.gov/38506892/ | L39: Non-English therapy chatbot efficacy | M39: 81 participants | N39: Polish-speaking young adults | O39: 2-arm RCT | P39: CBT chatbot | Q39: Text | R39: Depression/anxiety | S39: Clinical scales | T39: Evaluated Polish-language chatbot efficacy | U39: Small/short; non-pregnancy population | V39: Evidence that non-English CA evaluation is feasible | W39: Sinhala pregnancy CA remains open | X39: Bilingual evaluation approach
A40: T1 | B40: Therapeutic Music & Digital Interventions | C40: (N/A — not Behavioural Track) | D40: Extracted | E40: Tier 1 | F40: Yes | G40: Lin et al. | H40: 2019 | I40: Music Interventions for Anxiety in Pregnant Women: A Systematic Review and Meta-Analysis of Randomized Controlled Trials | J40: Journal of Clinical Medicine | K40: https://doi.org/10.3390/jcm8111884 | L40: Effect of music during pregnancy on anxiety | M40: 11 RCTs, 1482 participants | N40: Pregnant women | O40: Systematic review/meta-analysis | P40: RCT meta-analysis | Q40: Music | R40: Anxiety | S40: SMD | T40: SMD -0.42 overall; home listening significant | U40: High heterogeneity | V40: Supports supportive music recommendation | W40: Need mood-triggered digital delivery | X40: Conservative evidence-based wording
A41: T2 | B41: Therapeutic Music & Digital Interventions | C41: (N/A — not Behavioural Track) | D41: Extracted | E41: Tier 1 | F41: Yes | G41: Alder et al. | H41: 2017 | I41: Music interventions to reduce stress and anxiety in pregnancy: a systematic review and meta-analysis | J41: BMC Psychiatry | K41: https://doi.org/10.1186/s12888-017-1432-x | L41: Effect of music-based interventions in pregnancy | M41: 5 studies, 1261 women | N41: Pregnant women | O41: Systematic review/meta-analysis | P41: RCT/quasi-experimental | Q41: Music | R41: Anxiety/stress | S41: SMD | T41: Anxiety reduced SMD -0.21; stress not significant | U41: Moderate-weak quality | V41: Evidence supports anxiety more than stress | W41: Need targeted digital recommendation | X41: Do not claim clinical treatment
...

Sheet Lists
A1: Maternal Mental Health / Sri Lanka Context | B1: (N/A — not Behavioural Track) | C1: Candidate | D1: Tier 1 | E1: Yes
A2: Existing Pregnancy-Support & Mental-Health Apps | B2: Typing Speed & Emotion | C2: Screened Out | D2: Tier 2 | E2: No
A3: Conversational Agents for Mental Health | B3: Response Delay & Emotion | C3: Extracted | D3: Tier 3 | E3: Pending
A4: Facial Emotion Recognition (incl. Head-Pose) | B4: Keystroke/Behavioural Affect (general) | C4: Cited in Final
A5: English Sentiment / Transformers | B5: Individual- vs Population-Level Inference
A6: Sinhala / Low-Resource NLP | B6: Device/Keyboard Confounds
A7: Multimodal Fusion | B7: Sinhala vs English Typing Differences
A8: Adaptive / Affect-Conditioned Response
A9: Therapeutic Music & Digital Interventions
A10: Privacy / Ethics / On-Device Inference
A11: Behavioural Signal Track
A12: Existing Systems (Section H)

Sheet Progress Tracker
A1: Topic | B1: Min Target | C1: Recommended Target | D1: Max Target | E1: # Candidate | F1: # Extracted | G1: # Cited in Final | H1: # Verified = Yes | I1: Status vs Recommended
A2: Maternal Mental Health / Sri Lanka Context | B2: 4 | C2: 4 | D2: 5 | E2: =COUNTIFS('Master Extraction Sheet'!$B$2:$B$80,$A2,'Master Extraction Sheet'!$D$2:$D$80,"Candidate") | F2: =COUNTIFS('Master Extraction Sheet'!$B$2:$B$80,$A2,'Master Extraction Sheet'!$D$2:$D$80,"Extracted")+COUNTIFS('Master Extraction Sheet'!$B$2:$B$80,$A2,'Master Extraction Sheet'!$D$2:$D$80,"Cited in Final") | G2: =COUNTIFS('Master Extraction Sheet'!$B$2:$B$80,$A2,'Master Extraction Sheet'!$D$2:$D$80,"Cited in Final") | H2: =COUNTIFS('Master Extraction Sheet'!$B$2:$B$80,$A2,'Master Extraction Sheet'!$F$2:$F$80,"Yes") | I2: =IF(F2>=C2,"Target met",IF(F2>=B2,"Minimum met",IF(F2=0,"Not started","In progress")))
A3: Existing Pregnancy-Support & Mental-Health Apps | B3: 2 | C3: 2 | D3: 3 | E3: =COUNTIFS('Master Extraction Sheet'!$B$2:$B$80,$A3,'Master Extraction Sheet'!$D$2:$D$80,"Candidate") | F3: =COUNTIFS('Master Extraction Sheet'!$B$2:$B$80,$A3,'Master Extraction Sheet'!$D$2:$D$80,"Extracted")+COUNTIFS('Master Extraction Sheet'!$B$2:$B$80,$A3,'Master Extraction Sheet'!$D$2:$D$80,"Cited in Final") | G3: =COUNTIFS('Master Extraction Sheet'!$B$2:$B$80,$A3,'Master Extraction Sheet'!$D$2:$D$80,"Cited in Final") | H3: =COUNTIFS('Master Extraction Sheet'!$B$2:$B$80,$A3,'Master Extraction Sheet'!$F$2:$F$80,"Yes") | I3: =IF(F3>=C3,"Target met",IF(F3>=B3,"Minimum met",IF(F3=0,"Not started","In progress")))
A4: Conversational Agents for Mental Health | B4: 4 | C4: 5 | D4: 6 | E4: =COUNTIFS('Master Extraction Sheet'!$B$2:$B$80,$A4,'Master Extraction Sheet'!$D$2:$D$80,"Candidate") | F4: =COUNTIFS('Master Extraction Sheet'!$B$2:$B$80,$A4,'Master Extraction Sheet'!$D$2:$D$80,"Extracted")+COUNTIFS('Master Extraction Sheet'!$B$2:$B$80,$A4,'Master Extraction Sheet'!$D$2:$D$80,"Cited in Final") | G4: =COUNTIFS('Master Extraction Sheet'!$B$2:$B$80,$A4,'Master Extraction Sheet'!$D$2:$D$80,"Cited in Final") | H4: =COUNTIFS('Master Extraction Sheet'!$B$2:$B$80,$A4,'Master Extraction Sheet'!$F$2:$F$80,"Yes") | I4: =IF(F4>=C4,"Target met",IF(F4>=B4,"Minimum met",IF(F4=0,"Not started","In progress")))
A5: Facial Emotion Recognition (incl. Head-Pose) | B5: 5 | C5: 6 | D5: 7 | E5: =COUNTIFS('Master Extraction Sheet'!$B$2:$B$80,$A5,'Master Extraction Sheet'!$D$2:$D$80,"Candidate") | F5: =COUNTIFS('Master Extraction Sheet'!$B$2:$B$80,$A5,'Master Extraction Sheet'!$D$2:$D$80,"Extracted")+COUNTIFS('Master Extraction Sheet'!$B$2:$B$80,$A5,'Master Extraction Sheet'!$D$2:$D$80,"Cited in Final") | G5: =COUNTIFS('Master Extraction Sheet'!$B$2:$B$80,$A5,'Master Extraction Sheet'!$D$2:$D$80,"Cited in Final") | H5: =COUNTIFS('Master Extraction Sheet'!$B$2:$B$80,$A5,'Master Extraction Sheet'!$F$2:$F$80,"Yes") | I5: =IF(F5>=C5,"Target met",IF(F5>=B5,"Minimum met",IF(F5=0,"Not started","In progress")))
A6: English Sentiment / Transformers | B6: 3 | C6: 4 | D6: 4 | E6: =COUNTIFS('Master Extraction Sheet'!$B$2:$B$80,$A6,'Master Extraction Sheet'!$D$2:$D$80,"Candidate") | F6: =COUNTIFS('Master Extraction Sheet'!$B$2:$B$80,$A6,'Master Extraction Sheet'!$D$2:$D$80,"Extracted")+COUNTIFS('Master Extraction Sheet'!$B$2:$B$80,$A6,'Master Extraction Sheet'!$D$2:$D$80,"Cited in Final") | G6: =COUNTIFS('Master Extraction Sheet'!$B$2:$B$80,$A6,'Master Extraction Sheet'!$D$2:$D$80,"Cited in Final") | H6: =COUNTIFS('Master Extraction Sheet'!$B$2:$B$80,$A6,'Master Extraction Sheet'!$F$2:$F$80,"Yes") | I6: =IF(F6>=C6,"Target met",IF(F6>=B6,"Minimum met",IF(F6=0,"Not started","In progress")))
A7: Sinhala / Low-Resource NLP | B7: 5 | C7: 6 | D7: 7 | E7: =COUNTIFS('Master Extraction Sheet'!$B$2:$B$80,$A7,'Master Extraction Sheet'!$D$2:$D$80,"Candidate") | F7: =COUNTIFS('Master Extraction Sheet'!$B$2:$B$80,$A7,'Master Extraction Sheet'!$D$2:$D$80,"Extracted")+COUNTIFS('Master Extraction Sheet'!$B$2:$B$80,$A7,'Master Extraction Sheet'!$D$2:$D$80,"Cited in Final") | G7: =COUNTIFS('Master Extraction Sheet'!$B$2:$B$80,$A7,'Master Extraction Sheet'!$D$2:$D$80,"Cited in Final") | H7: =COUNTIFS('Master Extraction Sheet'!$B$2:$B$80,$A7,'Master Extraction Sheet'!$F$2:$F$80,"Yes") | I7: =IF(F7>=C7,"Target met",IF(F7>=B7,"Minimum met",IF(F7=0,"Not started","In progress")))
A8: Multimodal Fusion | B8: 4 | C8: 4 | D8: 5 | E8: =COUNTIFS('Master Extraction Sheet'!$B$2:$B$80,$A8,'Master Extraction Sheet'!$D$2:$D$80,"Candidate") | F8: =COUNTIFS('Master Extraction Sheet'!$B$2:$B$80,$A8,'Master Extraction Sheet'!$D$2:$D$80,"Extracted")+COUNTIFS('Master Extraction Sheet'!$B$2:$B$80,$A8,'Master Extraction Sheet'!$D$2:$D$80,"Cited in Final") | G8: =COUNTIFS('Master Extraction Sheet'!$B$2:$B$80,$A8,'Master Extraction Sheet'!$D$2:$D$80,"Cited in Final") | H8: =COUNTIFS('Master Extraction Sheet'!$B$2:$B$80,$A8,'Master Extraction Sheet'!$F$2:$F$80,"Yes") | I8: =IF(F8>=C8,"Target met",IF(F8>=B8,"Minimum met",IF(F8=0,"Not started","In progress")))
A9: Adaptive / Affect-Conditioned Response | B9: 3 | C9: 4 | D9: 4 | E9: =COUNTIFS('Master Extraction Sheet'!$B$2:$B$80,$A9,'Master Extraction Sheet'!$D$2:$D$80,"Candidate") | F9: =COUNTIFS('Master Extraction Sheet'!$B$2:$B$80,$A9,'Master Extraction Sheet'!$D$2:$D$80,"Extracted")+COUNTIFS('Master Extraction Sheet'!$B$2:$B$80,$A9,'Master Extraction Sheet'!$D$2:$D$80,"Cited in Final") | G9: =COUNTIFS('Master Extraction Sheet'!$B$2:$B$80,$A9,'Master Extraction Sheet'!$D$2:$D$80,"Cited in Final") | H9: =COUNTIFS('Master Extraction Sheet'!$B$2:$B$80,$A9,'Master Extraction Sheet'!$F$2:$F$80,"Yes") | I9: =IF(F9>=C9,"Target met",IF(F9>=B9,"Minimum met",IF(F9=0,"Not started","In progress")))
A10: Therapeutic Music & Digital Interventions | B10: 2 | C10: 2 | D10: 3 | E10: =COUNTIFS('Master Extraction Sheet'!$B$2:$B$80,$A10,'Master Extraction Sheet'!$D$2:$D$80,"Candidate") | F10: =COUNTIFS('Master Extraction Sheet'!$B$2:$B$80,$A10,'Master Extraction Sheet'!$D$2:$D$80,"Extracted")+COUNTIFS('Master Extraction Sheet'!$B$2:$B$80,$A10,'Master Extraction Sheet'!$D$2:$D$80,"Cited in Final") | G10: =COUNTIFS('Master Extraction Sheet'!$B$2:$B$80,$A10,'Master Extraction Sheet'!$D$2:$D$80,"Cited in Final") | H10: =COUNTIFS('Master Extraction Sheet'!$B$2:$B$80,$A10,'Master Extraction Sheet'!$F$2:$F$80,"Yes") | I10: =IF(F10>=C10,"Target met",IF(F10>=B10,"Minimum met",IF(F10=0,"Not started","In progress")))
A11: Privacy / Ethics / On-Device Inference | B11: 2 | C11: 2 | D11: 3 | E11: =COUNTIFS('Master Extraction Sheet'!$B$2:$B$80,$A11,'Master Extraction Sheet'!$D$2:$D$80,"Candidate") | F11: =COUNTIFS('Master Extraction Sheet'!$B$2:$B$80,$A11,'Master Extraction Sheet'!$D$2:$D$80,"Extracted")+COUNTIFS('Master Extraction Sheet'!$B$2:$B$80,$A11,'Master Extraction Sheet'!$D$2:$D$80,"Cited in Final") | G11: =COUNTIFS('Master Extraction Sheet'!$B$2:$B$80,$A11,'Master Extraction Sheet'!$D$2:$D$80,"Cited in Final") | H11: =COUNTIFS('Master Extraction Sheet'!$B$2:$B$80,$A11,'Master Extraction Sheet'!$F$2:$F$80,"Yes") | I11: =IF(F11>=C11,"Target met",IF(F11>=B11,"Minimum met",IF(F11=0,"Not started","In progress")))
A12: Behavioural Signal Track | B12: 4 | C12: 5 | D12: 6 | E12: =COUNTIFS('Master Extraction Sheet'!$B$2:$B$80,$A12,'Master Extraction Sheet'!$D$2:$D$80,"Candidate") | F12: =COUNTIFS('Master Extraction Sheet'!$B$2:$B$80,$A12,'Master Extraction Sheet'!$D$2:$D$80,"Extracted")+COUNTIFS('Master Extraction Sheet'!$B$2:$B$80,$A12,'Master Extraction Sheet'!$D$2:$D$80,"Cited in Final") | G12: =COUNTIFS('Master Extraction Sheet'!$B$2:$B$80,$A12,'Master Extraction Sheet'!$D$2:$D$80,"Cited in Final") | H12: =COUNTIFS('Master Extraction Sheet'!$B$2:$B$80,$A12,'Master Extraction Sheet'!$F$2:$F$80,"Yes") | I12: =IF(F12>=C12,"Target met",IF(F12>=B12,"Minimum met",IF(F12=0,"Not started","In progress")))
A13: Existing Systems (Section H) | B13: 9 | C13: 10 | D13: 12 | E13: =COUNTIFS('Master Extraction Sheet'!$B$2:$B$80,$A13,'Master Extraction Sheet'!$D$2:$D$80,"Candidate") | F13: =COUNTIFS('Master Extraction Sheet'!$B$2:$B$80,$A13,'Master Extraction Sheet'!$D$2:$D$80,"Extracted")+COUNTIFS('Master Extraction Sheet'!$B$2:$B$80,$A13,'Master Extraction Sheet'!$D$2:$D$80,"Cited in Final") | G13: =COUNTIFS('Master Extraction Sheet'!$B$2:$B$80,$A13,'Master Extraction Sheet'!$D$2:$D$80,"Cited in Final") | H13: =COUNTIFS('Master Extraction Sheet'!$B$2:$B$80,$A13,'Master Extraction Sheet'!$F$2:$F$80,"Yes") | I13: =IF(F13>=C13,"Target met",IF(F13>=B13,"Minimum met",IF(F13=0,"Not started","In progress")))
A14: TOTAL | B14: =SUM(B2:B13) | C14: =SUM(C2:C13) | D14: =SUM(D2:D13) | E14: =COUNTIFS('Master Extraction Sheet'!$B$2:$B$80,$A14,'Master Extraction Sheet'!$D$2:$D$80,"Candidate") | F14: =COUNTIFS('Master Extraction Sheet'!$B$2:$B$80,$A14,'Master Extraction Sheet'!$D$2:$D$80,"Extracted")+COUNTIFS('Master Extraction Sheet'!$B$2:$B$80,$A14,'Master Extraction Sheet'!$D$2:$D$80,"Cited in Final") | G14: =COUNTIFS('Master Extraction Sheet'!$B$2:$B$80,$A14,'Master Extraction Sheet'!$D$2:$D$80,"Cited in Final") | H14: =COUNTIFS('Master Extraction Sheet'!$B$2:$B$80,$A14,'Master Extraction Sheet'!$F$2:$F$80,"Yes") | I14: =IF(F14>=C14,"Target met",IF(F14>=B14,"Minimum met",IF(F14=0,"Not started","In progress")))
A16: Blue cells are fixed targets from the Master Plan (Section C/G/H) — do not edit unless scope changes. All other numbers recalculate automatically from the Master Extraction Sheet.

Sheet Behavioural Signal Track
A1: Behavioural Signal Decision Track (Master Plan Section G)
A2: Resolve this before finalizing §3.2.6 fusion methodology. Papers logged here should use Topic = 'Behavioural Signal Track' in the Master Extraction Sheet, with the matching Sub-topic value.
A4: Sub-topic | B4: Question to Answer | C4: Target Papers | D4: # Extracted (auto) | E4: Finding (fill in once resolved)
A5: Typing Speed & Emotion | B5: Does typing speed predict mood at the individual/message level, or only population-level? | C5: 1–2 | D5: =COUNTIFS('Master Extraction Sheet'!$C$2:$C$80,A5,'Master Extraction Sheet'!$D$2:$D$80,"Extracted")+COUNTIFS('Master Extraction Sheet'!$C$2:$C$80,A5,'Master Extraction Sheet'!$D$2:$D$80,"Cited in Final") | E5: Evidence exists, but effects are sensitive to individual variability; generic fixed weighting is weakly justified.
A6: Response Delay & Emotion | B6: Same individual-vs-population distinction, for inter-message response latency | C6: 1–2 | D6: =COUNTIFS('Master Extraction Sheet'!$C$2:$C$80,A6,'Master Extraction Sheet'!$D$2:$D$80,"Extracted")+COUNTIFS('Master Extraction Sheet'!$C$2:$C$80,A6,'Master Extraction Sheet'!$D$2:$D$80,"Cited in Final") | E6: Evidence shows associations with affect, but not a validated per-message mood classifier in this pregnancy-chat context.
A7: Keystroke/Behavioural Affect (general) | B7: Best reported accuracy for behaviour-only affect classification, and under what conditions? | C7: 1–2 | D7: =COUNTIFS('Master Extraction Sheet'!$C$2:$C$80,A7,'Master Extraction Sheet'!$D$2:$D$80,"Extracted")+COUNTIFS('Master Extraction Sheet'!$C$2:$C$80,A7,'Master Extraction Sheet'!$D$2:$D$80,"Cited in Final") | E7: Smartphone evidence is promising but strongly favors personalized models and self-report calibration.
A8: Individual- vs Population-Level Inference | B8: Does ANY paper validate behavioural signals as a real-time per-instance classifier with reported accuracy? | C8: cross-check above | D8: =COUNTIFS('Master Extraction Sheet'!$C$2:$C$80,A8,'Master Extraction Sheet'!$D$2:$D$80,"Extracted")+COUNTIFS('Master Extraction Sheet'!$C$2:$C$80,A8,'Master Extraction Sheet'!$D$2:$D$80,"Cited in Final") | E8: No strong evidence found here for a generic, pregnancy-specific, individual-level response-delay/typing classifier suitable for a fixed 15% fusion weight.
A9: Device/Keyboard Confounds | B9: Has any study controlled for device/keyboard/IME/connection speed when measuring typing-based affect? | C9: 1 | D9: =COUNTIFS('Master Extraction Sheet'!$C$2:$C$80,A9,'Master Extraction Sheet'!$D$2:$D$80,"Extracted")+COUNTIFS('Master Extraction Sheet'!$C$2:$C$80,A9,'Master Extraction Sheet'!$D$2:$D$80,"Cited in Final")
A10: Sinhala vs English Typing Differences | B10: Is there a published baseline for Sinhala Unicode typing speed vs English, independent of mood? | C10: 0–1 (absence itself is a finding) | D10: =COUNTIFS('Master Extraction Sheet'!$C$2:$C$80,A10,'Master Extraction Sheet'!$D$2:$D$80,"Extracted")+COUNTIFS('Master Extraction Sheet'!$C$2:$C$80,A10,'Master Extraction Sheet'!$D$2:$D$80,"Cited in Final")
A12: Decision Rule
A13: 1. If ≥2 Tier 1/2 sources show individual-level, per-instance validated behavioural affect classification with a reported accuracy metric → KEEP in fusion, using that metric to justify a defensible weight.
A14: 2. If evidence found is exclusively population-level/correlational → REMOVE from fused mood score; retain as logged, unfused telemetry only.
A15: 3. If evidence is genuinely mixed or thin → default to telemetry-only. An unvalidated signal shaping responses to a vulnerable population carries more downside than the upside of keeping a weak signal in fusion.
A17: FINAL DECISION (fill in once track is complete) | C17: [ KEEP / REMOVE / TELEMETRY-ONLY ]
A18: Reasoning:
